# JavaScript 专题之 Promise

## Promise 的局限性

1. 错误被吃掉
   首先我们要理解，什么是错误被吃掉，是指错误信息不被打印吗？

并不是，举个例子：

```js
throw new Error('error')
console.log(233333)
```

在这种情况下，因为 throw error 的缘故，代码被阻断执行，并不会打印 233333，再举个例子：

```js
let promise = new Promise(() => {
  throw new Error('error')
})
console.log(2333333)
```

这次会正常的打印 233333，说明 **Promise 内部的错误不会影响到 Promise 外部的代码，而这种情况我们就通常称为 “吃掉错误”。**

2. 单一值

3. 无法取消

4. 无法得知 pending 状态

## promisify

什么是 promisify 呢？ 顾名思义，就是“promise 化”，将一个不是 promise 的方法变成 promise 。

## 如何手写 promise

```js
const PENDING = 'PENDING'
const FULFILLED = 'FULFILLED'
const REJECTED = 'REJECTED'
class MyPromise {
  constructor(func) {
    // 默认状态为 PENDING

    this.status = PENDING
    // 存放成功状态的值，默认为 undefined
    this.value = undefined
    // 存放失败状态的值，默认为 undefined
    this.reason = undefined
    this.onResolvedCallbacks = []
    this.onRejectedCallbacks = []
    console.log('执行构造函数')

    // 调用此方法就是成功
    let resolve = (value) => {
      // 状态为 PENDING 时才可以更新状态，防止 executor 中调用了两次 resovle/reject 方法
      if (this.status === PENDING) {
        this.status = FULFILLED
        this.value = value
        this.onResolvedCallbacks.forEach((ele) => ele())
      }
    }

    // 调用此方法就是失败
    let reject = (reason) => {
      // 状态为 PENDING 时才可以更新状态，防止 executor 中调用了两次 resovle/reject 方法
      if (this.status === PENDING) {
        this.status = REJECTED
        this.reason = reason
        this.onRejectedCallbacks.forEach((ele) => ele())
      }
    }

    try {
      // 立即执行，将 resolve 和 reject 函数传给使用者
      func(resolve, reject)
    } catch (error) {
      // 发生异常时执行失败逻辑
      reject(error)
    }
  }

  then(onFulfilled, onRejected) {
    if (this.status === FULFILLED) {
      onFulfilled(this.value)
    }
    if (this.status === REJECTED) {
      onRejected(this.reason)
    }
    if (this.status === PENDING) {
      // 如果promise的状态是 pending，需要将 onFulfilled 和 onRejected 函数存放起来，等待状态确定后，再依次将对应的函数执行
      this.onResolvedCallbacks.push(() => {
        onFulfilled(this.value)
      })

      // 如果promise的状态是 pending，需要将 onFulfilled 和 onRejected 函数存放起来，等待状态确定后，再依次将对应的函数执行
      this.onRejectedCallbacks.push(() => {
        onRejected(this.reason)
      })
    }
  }
}

//测试异步
const mypromise = new MyPromise((resolve, reject) => {
  setTimeout(() => {
    resolve('成功')
  }, 2000)
}).then(
  (data) => {
    console.log('success', data)
  },
  (err) => {
    console.log('faild', err)
  }
)
//测试主动抛出异常执行 reject
const mypromise1 = new MyPromise((resolve, reject) => {
  throw new Error('主动报错')
}).then(
  (data) => {
    console.log('success', data)
  },
  (err) => {
    console.log('faild', err)
  }
)
```
